Workbook

Sheet Sheet1
A1: 테이블정의서
A2: 엔티티 타입명 | B2: 회원 | C2: 작성일 | D2: 44481
A3: 테이블명 | B3: MEM | C3: 작성자 | D3: 조명석
A4: 테이블 설명 | B4: 회원테이블
A5: 번호 | B5: 컬럼명 | C5: 속성명 | D5: 도메인 | E5: 데이터타입 | F5: NULL여부 | G5: 기본값 | H5: KEY
A6: 1 | B6: MEM_ID | C6: 아이디 | D6: N/A | E6: VARCHAR2(100) | F6: Not Null | H6: PK
A7: 2 | B7: MEM_PASS | C7: 비밀번호 | D7: N/A | E7: VARCHAR2(100) | F7: Not Null
A8: 3 | B8: MEM_GROUP | C8: 구분 | D8: N/A | E8: CHAR(3) | F8: Not Null
A9: 4 | B9: MEM_START | C9: 입학일 | D9: N/A | E9: DATE | F9: Null
A10: 5 | B10: MEM_END | C10: 졸업일 | D10: N/A | E10: DATE | F10: Null
A11: 6 | B11: MEM_ADDR1 | C11: 주소 | D11: N/A | E11: VARCHAR2(200) | F11: Null
A12: 7 | B12: MEM_ADDR2 | C12: 주소 상세 | D12: N/A | E12: VARCHAR2(100) | F12: Null
A13: 8 | B13: MEM_HP | C13: 핸드폰 | D13: N/A | E13: VARCHAR2(13) | F13: Null
A14: 9 | B14: MEM_NAME | C14: 이름 | D14: N/A | E14: VARCHAR2(50) | F14: Not Null
A15: 10 | B15: MEM_SUB | C15: 과목 | D15: N/A | E15: VARCHAR2(100) | F15: Not Null
A16: 11 | B16: CLASS_ID | C16: 반 아이디 | D16: N/A | E16: CHAR(4) | F16: Null | H16: FK
A18: 테이블정의서
A19: 엔티티 타입명 | B19: 관리자 | C19: 작성일 | D19: 44481
A20: 테이블명 | B20: ADMIN | C20: 작성자 | D20: 조명석
A21: 테이블 설명 | B21: 회원테이블
A22: 번호 | B22: 컬럼명 | C22: 속성명 | D22: 도메인 | E22: 데이터타입 | F22: NULL여부 | G22: 기본값 | H22: KEY
A23: 1 | B23: ADMIN_ID | C23: 아이디 | D23: N/A | E23: VARCHAR2(100) | F23: Not Null | H23: PK
A24: 2 | B24: ADMIN_PW | C24: 비밀번호 | D24: N/A | E24: VARCHAR2(100) | F24: Not Null
A26: 테이블정의서
A27: 엔티티 타입명 | B27: 반 게시판 | C27: 작성일 | D27: 44481
A28: 테이블명 | B28: CLBOARD | C28: 작성자 | D28: 조명석
A29: 테이블 설명 | B29: 회원테이블
A30: 번호 | B30: 컬럼명 | C30: 속성명 | D30: 도메인 | E30: 데이터타입 | F30: NULL여부 | G30: 기본값 | H30: KEY
A31: 1 | B31: CLBOARD_NUM | C31: 게시판번호 | D31: N/A | E31: NUMBER | F31: Not Null | H31: PK
A32: 2 | B32: ADMINBOARD_ID | C32: 게시판 아이디 | D32: N/A | E32: char(10) | F32: Not Null | H32: PK,FK
A33: 3 | B33: CLBOARD_TITLE | C33: 제목 | D33: N/A | E33: VARCHAR2(100) | F33: Not Null
A34: 4 | B34: CLBOARD_DATE | C34: 날짜 | D34: N/A | E34: DATE | F34: Not Null
A35: 5 | B35: CLBOARD_CONTENT | C35: 내용 | D35: N/A | E35: VARCHAR2(500) | F35: Not Null
A36: 6 | B36: CLBOARD_GROUP | C36: 구분 | D36: N/A | E36: char(4) | F36: Not Null
A37: 7 | B37: MEM_ID | C37: 아이디 | D37: N/A | E37: VARCHAR2(100) | F37: Not Null | H37: FK
A39: 테이블정의서
A40: 엔티티 타입명 | B40: 전체 게시판 | C40: 작성일 | D40: 44481
A41: 테이블명 | B41: BOARD | C41: 작성자 | D41: 조명석
A42: 테이블 설명 | B42: 회원테이블
A43: 번호 | B43: 컬럼명 | C43: 속성명 | D43: 도메인 | E43: 데이터타입 | F43: NULL여부 | G43: 기본값 | H43: KEY
...

Sheet Sheet2
B2: =UPPER(Sheet1!B2) -> 회원 | C2: =UPPER(Sheet1!C2) -> 작성일 | D2: =UPPER(Sheet1!D2) -> 44481 | E2: =UPPER(Sheet1!E2)
B3: =UPPER(Sheet1!B3) -> MEM | E3: =UPPER(Sheet1!E3)
B4: =UPPER(Sheet1!B4) -> 회원테이블 | E4: =UPPER(Sheet1!E4)
B5: =UPPER(Sheet1!B5) -> 컬럼명 | E5: =UPPER(Sheet1!E5) -> 데이터타입
B6: =UPPER(Sheet1!B6) -> MEM_ID | E6: =UPPER(Sheet1!E6) -> VARCHAR2(100)
B7: =UPPER(Sheet1!B7) -> MEM_PASS | E7: =UPPER(Sheet1!E7) -> VARCHAR2(100)
B8: =UPPER(Sheet1!B8) -> MEM_GROUP | E8: =UPPER(Sheet1!E8) -> CHAR(3)
B9: =UPPER(Sheet1!B9) -> MEM_START | E9: =UPPER(Sheet1!E9) -> DATE
B10: =UPPER(Sheet1!B10) -> MEM_END | E10: =UPPER(Sheet1!E10) -> DATE
B11: =UPPER(Sheet1!B11) -> MEM_ADDR1 | E11: =UPPER(Sheet1!E11) -> VARCHAR2(200)
B12: =UPPER(Sheet1!B12) -> MEM_ADDR2 | E12: =UPPER(Sheet1!E12) -> VARCHAR2(100)
B13: =UPPER(Sheet1!B13) -> MEM_HP | E13: =UPPER(Sheet1!E13) -> VARCHAR2(13)
B14: =UPPER(Sheet1!B14) -> MEM_NAME | E14: =UPPER(Sheet1!E14) -> VARCHAR2(50)
... B142: =UPPER(Sheet1!B142) -> MEM_ID | E142: =UPPER(Sheet1!E142) -> VARCHAR2(100)
B143: =UPPER(Sheet1!#REF!) -> #REF! | E143: =UPPER(Sheet1!E143)
B144: =UPPER(Sheet1!#REF!) -> #REF! | E144: =UPPER(Sheet1!E144)
B145: =UPPER(Sheet1!#REF!) -> #REF! | E145: =UPPER(Sheet1!E145)
B146: =UPPER(Sheet1!#REF!) -> #REF! | E146: =UPPER(Sheet1!E146)
B147: =UPPER(Sheet1!#REF!) -> #REF! | E147: =UPPER(Sheet1!E147)
B148: =UPPER(Sheet1!#REF!) -> #REF! | E148: =UPPER(Sheet1!E148) -> 데이터타입
B149: =UPPER(Sheet1!#REF!) -> #REF! | E149: =UPPER(Sheet1!E149) -> NUMBER
B150: =UPPER(Sheet1!#REF!) -> #REF! | E150: =UPPER(Sheet1!E150) -> DATE
B151: =UPPER(Sheet1!#REF!) -> #REF! | E151: =UPPER(Sheet1!E151) -> CHAR(1)
B152: =UPPER(Sheet1!#REF!) -> #REF! | E152: =UPPER(Sheet1!E152) -> CHAR(10)
B153: =UPPER(Sheet1!B143) | E153: =UPPER(Sheet1!E153)
B154: =UPPER(Sheet1!B144) | E154: =UPPER(Sheet1!E154)
B155: =UPPER(Sheet1!B145) -> 첨부파일 | E155: =UPPER(Sheet1!E155)
B156: =UPPER(Sheet1!B146) -> ATCH_FILE | E156: =UPPER(Sheet1!E156)
B157: =UPPER(Sheet1!B147) -> 회원테이블 | E157: =UPPER(Sheet1!E157)
B158: =UPPER(Sheet1!B148) -> 컬럼명 | E158: =UPPER(Sheet1!E158) -> 데이터타입
B159: =UPPER(Sheet1!B149) -> ATCH_FILE_ID | E159: =UPPER(Sheet1!E159) -> NUMBER
B160: =UPPER(Sheet1!B150) -> ATCH_FILE_DATE | E160: =UPPER(Sheet1!E160) -> NUMBER(3,0)
B161: =UPPER(Sheet1!B151) -> USE_AT | E161: =UPPER(Sheet1!E161) -> VARCHAR2(2000)
B162: =UPPER(Sheet1!B152) -> ADMINBOARD_ID | E162: =UPPER(Sheet1!E162) -> VARCHAR2(255)
B163: =UPPER(Sheet1!B153) | E163: =UPPER(Sheet1!E163) -> VARCHAR2(255)
B164: =UPPER(Sheet1!B154) | E164: =UPPER(Sheet1!E164) -> VARCHAR2(20)
... B186: =UPPER(Sheet1!B176) -> ITT_END | E186: =UPPER(Sheet1!E186) -> VARCHAR2(50)
B187: =UPPER(Sheet1!#REF!) -> #REF! | E187: =UPPER(Sheet1!E187) -> DATE
B188: =UPPER(Sheet1!B177) -> ITT_COLOR | E188: =UPPER(Sheet1!E188) -> DATE
B189: =UPPER(Sheet1!B178) -> ITT_OVERLAP | E189: =UPPER(Sheet1!E189) -> CHAR(1)
...

Sheet Sheet3
